INFO:     Will watch for changes in these directories: ['/home/workspace']
INFO:     Uvicorn running on http://0.0.0.0:8000 (Press CTRL+C to quit)
INFO:     Started reloader process [174] using StatReload
Process SpawnProcess-1:
Traceback (most recent call last):
  File "/usr/local/lib/python3.13/site-packages/pydantic/networks.py", line 946, in import_email_validator
    import email_validator
ModuleNotFoundError: No module named 'email_validator'

The above exception was the direct cause of the following exception:

Traceback (most recent call last):
  File "/usr/local/lib/python3.13/multiprocessing/process.py", line 313, in _bootstrap
    self.run()
    ~~~~~~~~^^
  File "/usr/local/lib/python3.13/multiprocessing/process.py", line 108, in run
    self._target(*self._args, **self._kwargs)
    ~~~~~~~~~~~~^^^^^^^^^^^^^^^^^^^^^^^^^^^^^
  File "/usr/local/lib/python3.13/site-packages/uvicorn/_subprocess.py", line 76, in subprocess_started
    target(sockets=sockets)
    ~~~~~~^^^^^^^^^^^^^^^^^
  File "/usr/local/lib/python3.13/site-packages/uvicorn/server.py", line 61, in run
    return asyncio.run(self.serve(sockets=sockets))
           ~~~~~~~~~~~^^^^^^^^^^^^^^^^^^^^^^^^^^^^^
  File "/usr/local/lib/python3.13/asyncio/runners.py", line 195, in run
    return runner.run(main)
           ~~~~~~~~~~^^^^^^
  File "/usr/local/lib/python3.13/asyncio/runners.py", line 118, in run
    return self._loop.run_until_complete(task)
           ~~~~~~~~~~~~~~~~~~~~~~~~~~~~~^^^^^^
  File "/usr/local/lib/python3.13/asyncio/base_events.py", line 725, in run_until_complete
    return future.result()
           ~~~~~~~~~~~~~^^
  File "/usr/local/lib/python3.13/site-packages/uvicorn/server.py", line 68, in serve
    config.load()
    ~~~~~~~~~~~^^
  File "/usr/local/lib/python3.13/site-packages/uvicorn/config.py", line 467, in load
    self.loaded_app = import_from_string(self.app)
                      ~~~~~~~~~~~~~~~~~~^^^^^^^^^^
  File "/usr/local/lib/python3.13/site-packages/uvicorn/importer.py", line 21, in import_from_string
    module = importlib.import_module(module_str)
  File "/usr/local/lib/python3.13/importlib/__init__.py", line 88, in import_module
    return _bootstrap._gcd_import(name[level:], package, level)
           ~~~~~~~~~~~~~~~~~~~~~~^^^^^^^^^^^^^^^^^^^^^^^^^^^^^^
  File "<frozen importlib._bootstrap>", line 1387, in _gcd_import
  File "<frozen importlib._bootstrap>", line 1360, in _find_and_load
  File "<frozen importlib._bootstrap>", line 1331, in _find_and_load_unlocked
  File "<frozen importlib._bootstrap>", line 935, in _load_unlocked
  File "<frozen importlib._bootstrap_external>", line 1026, in exec_module
  File "<frozen importlib._bootstrap>", line 488, in _call_with_frames_removed
  File "/home/workspace/main.py", line 17, in <module>
    class ContactPayload(BaseModel):
    ...<3 lines>...
        message: str = Field(..., min_length=5, max_length=5000)
  File "/usr/local/lib/python3.13/site-packages/pydantic/_internal/_model_construction.py", line 237, in __new__
    complete_model_class(
    ~~~~~~~~~~~~~~~~~~~~^
        cls,
        ^^^^
    ...<3 lines>...
        create_model_module=_create_model_module,
        ^^^^^^^^^^^^^^^^^^^^^^^^^^^^^^^^^^^^^^^^^
    )
    ^
  File "/usr/local/lib/python3.13/site-packages/pydantic/_internal/_model_construction.py", line 597, in complete_model_class
    schema = gen_schema.generate_schema(cls)
  File "/usr/local/lib/python3.13/site-packages/pydantic/_internal/_generate_schema.py", line 711, in generate_schema
    schema = self._generate_schema_inner(obj)
  File "/usr/local/lib/python3.13/site-packages/pydantic/_internal/_generate_schema.py", line 1004, in _generate_schema_inner
    return self._model_schema(obj)
           ~~~~~~~~~~~~~~~~~~^^^^^
  File "/usr/local/lib/python3.13/site-packages/pydantic/_internal/_generate_schema.py", line 837, in _model_schema
    {k: self._generate_md_field_schema(k, v, decorators) for k, v in fields.items()},
        ~~~~~~~~~~~~~~~~~~~~~~~~~~~~~~^^^^^^^^^^^^^^^^^^
  File "/usr/local/lib/python3.13/site-packages/pydantic/_internal/_generate_schema.py", line 1206, in _generate_md_field_schema
    common_field = self._common_field_schema(name, field_info, decorators)
  File "/usr/local/lib/python3.13/site-packages/pydantic/_internal/_generate_schema.py", line 1372, in _common_field_schema
    schema = self._apply_annotations(
        source_type,
        annotations + validators_from_decorators,
    )
  File "/usr/local/lib/python3.13/site-packages/pydantic/_internal/_generate_schema.py", line 2297, in _apply_annotations
    schema = get_inner_schema(source_type)
  File "/usr/local/lib/python3.13/site-packages/pydantic/_internal/_schema_generation_shared.py", line 83, in __call__
    schema = self._handler(source_type)
  File "/usr/local/lib/python3.13/site-packages/pydantic/_internal/_generate_schema.py", line 2276, in inner_handler
    schema = self._generate_schema_from_get_schema_method(obj, source_type)
  File "/usr/local/lib/python3.13/site-packages/pydantic/_internal/_generate_schema.py", line 900, in _generate_schema_from_get_schema_method
    schema = get_schema(
        source, CallbackGetCoreSchemaHandler(self._generate_schema_inner, self, ref_mode=ref_mode)
    )
  File "/usr/local/lib/python3.13/site-packages/pydantic/networks.py", line 986, in __get_pydantic_core_schema__
    import_email_validator()
    ~~~~~~~~~~~~~~~~~~~~~~^^
  File "/usr/local/lib/python3.13/site-packages/pydantic/networks.py", line 948, in import_email_validator
    raise ImportError('email-validator is not installed, run `pip install pydantic[email]`') from e
ImportError: email-validator is not installed, run `pip install pydantic[email]`
